Workbook
Name Slicer_DepartmentType: #N/A
Name Slicer_GenderCode: #N/A
Name Slicer_MaritalDesc: #N/A
Name Slicer_PayZone: #N/A
Name Slicer_Performance_Score: #N/A

Sheet employee_data
A1: EmpID | B1: FirstName | C1: LastName | D1: StartDate | E1: ExitDate | F1: Title | G1: Supervisor | H1: ADEmail | I1: BusinessUnit | J1: EmployeeStatus | K1: EmployeeType | L1: PayZone | M1: EmployeeClassificationType | N1: TerminationType | O1: TerminationDescription | P1: DepartmentType | Q1: Division | R1: DOB | S1: State | T1: JobFunctionDescription | U1: GenderCode | V1: LocationCode | W1: RaceDesc | X1: MaritalDesc | Y1: Performance Score | Z1: Current Employee Rating
A2: 3427 | B2: Uriah | C2: Bridges | D2: 43728 | F2: Production Technician I | G2: Peter Oneill | H2: uriah.bridges@bilearner.com | I2: CCDR | J2: Active | K2: Contract | L2: Zone C | M2: Temporary | N2: Unk | P2: Production | Q2: Finance & Accounting | R2: 25483 | S2: MA | T2: Accounting | U2: Female | V2: 34904 | W2: White | X2: Widowed | Y2: Fully Meets | Z2: 4
A3: 3428 | B3: Paula | C3: Small | D3: 44968 | F3: Production Technician I | G3: Renee Mccormick | H3: paula.small@bilearner.com | I3: EW | J3: Active | K3: Contract | L3: Zone A | M3: Part-Time | N3: Unk | P3: Production | Q3: Aerial | R3: 23984 | S3: MA | T3: Labor | U3: Male | V3: 6593 | W3: Hispanic | X3: Widowed | Y3: Fully Meets | Z3: 3
A4: 3429 | B4: Edward | C4: Buck | D4: 43444 | F4: Area Sales Manager | G4: Crystal Walker | H4: edward.buck@bilearner.com | I4: PL | J4: Active | K4: Full-Time | L4: Zone B | M4: Part-Time | N4: Unk | P4: Sales | Q4: General - Sga | R4: 33517 | S4: MA | T4: Assistant | U4: Male | V4: 2330 | W4: Hispanic | X4: Widowed | Y4: Fully Meets | Z4: 4
A5: 3430 | B5: Michael | C5: Riordan | D5: 44368 | F5: Area Sales Manager | G5: Rebekah Wright | H5: michael.riordan@bilearner.com | I5: CCDR | J5: Active | K5: Contract | L5: Zone A | M5: Full-Time | N5: Unk | P5: Sales | Q5: Finance & Accounting | R5: 35889 | S5: ND | T5: Clerk | U5: Male | V5: 58782 | W5: Other | X5: Single | Y5: Fully Meets | Z5: 2
A6: 3431 | B6: Jasmine | C6: Onque | D6: 43645 | F6: Area Sales Manager | G6: Jason Kim | H6: jasmine.onque@bilearner.com | I6: TNS | J6: Active | K6: Contract | L6: Zone A | M6: Temporary | N6: Unk | P6: Sales | Q6: General - Con | R6: 25444 | S6: FL | T6: Laborer | U6: Female | V6: 33174 | W6: Other | X6: Married | Y6: Fully Meets | Z6: 3
A7: 3432 | B7: Maruk | C7: Fraval | D7: 43847 | F7: Area Sales Manager | G7: Sheri Campos | H7: maruk.fraval@bilearner.com | I7: BPC | J7: Active | K7: Contract | L7: Zone B | M7: Full-Time | N7: Unk | P7: Sales | Q7: Field Operations | R7: 17991 | S7: CT | T7: Driver | U7: Male | V7: 6050 | W7: Black | X7: Married | Y7: Fully Meets | Z7: 3
A8: 3433 | B8: Latia | C8: Costa | D8: 44657 | E8: 45110 | F8: Area Sales Manager | G8: Jacob Braun | H8: latia.costa@bilearner.com | I8: WBL | J8: Active | K8: Full-Time | L8: Zone B | M8: Temporary | N8: Involuntary | O8: Me see picture nature degree benefit. | P8: Sales | Q8: General - Eng | R8: 15523 | S8: CA | T8: Technician | U8: Female | V8: 90007 | W8: Hispanic | X8: Divorced | Y8: Exceeds | Z8: 4
A9: 3434 | B9: Sharlene | C9: Terry | D9: 44141 | E9: 44955 | F9: Area Sales Manager | G9: Tracy Marquez | H9: sharlene.terry@bilearner.com | I9: CCDR | J9: Active | K9: Contract | L9: Zone C | M9: Full-Time | N9: Involuntary | O9: Blue community type skill story. | P9: Sales | Q9: Engineers | R9: 20886 | S9: OR | T9: Engineer | U9: Female | V9: 97756 | W9: White | X9: Divorced | Y9: Fully Meets | Z9: 2
A10: 3435 | B10: Jac | C10: McKinzie | D10: 43330 | F10: Area Sales Manager | G10: Sharon Becker | H10: jac.mckinzie@bilearner.com | I10: NEL | J10: Active | K10: Contract | L10: Zone B | M10: Part-Time | N10: Unk | P10: Sales | Q10: Executive | R10: 27164 | S10: TX | T10: Executive Assistant | U10: Male | V10: 78789 | W10: Black | X10: Widowed | Y10: Exceeds | Z10: 3
A11: 3436 | B11: Joseph | C11: Martins | D11: 44582 | E11: 45106 | F11: Area Sales Manager | G11: George Jenkins | H11: joseph.martins@bilearner.com | I11: BPC | J11: Active | K11: Part-Time | L11: Zone B | M11: Temporary | N11: Resignation | O11: Summer personal bag. | P11: Sales | Q11: Engineers | R11: 18213 | S11: TX | T11: Engineer | U11: Male | V11: 78207 | W11: Asian | X11: Widowed | Y11: Fully Meets | Z11: 5
A12: 3437 | B12: Myriam | C12: Givens | D12: 45142 | F12: Area Sales Manager | G12: Troy White | H12: myriam.givens@bilearner.com | I12: SVG | J12: Active | K12: Contract | L12: Zone B | M12: Temporary | N12: Unk | P12: Sales | Q12: Field Operations | R12: 23402 | S12: IN | T12: Technician | U12: Female | V12: 46204 | W12: Other | X12: Single | Y12: Fully Meets | Z12: 5
A13: 3438 | B13: Dheepa | C13: Nguyen | D13: 43322 | E13: 43773 | F13: Area Sales Manager | G13: Brian Miller | H13: dheepa.nguyen@bilearner.com | I13: MSC | J13: Active | K13: Full-Time | L13: Zone C | M13: Temporary | N13: Retirement | O13: Alone once than. More condition pay far. | P13: Sales | Q13: General - Con | R13: 17629 | S13: GA | T13: Technician | U13: Female | V13: 30428 | W13: Asian | X13: Married | Y13: Fully Meets | Z13: 3
A14: 3439 | B14: Bartholemew | C14: Khemmich | D14: 44706 | E14: 44892 | F14: Area Sales Manager | G14: Charles Parks | H14: bartholemew.khemmich@bilearner.com | I14: EW | J14: Active | K14: Full-Time | L14: Zone A | M14: Temporary | N14: Involuntary | O14: Foot in theory minute recognize test. | P14: Sales | Q14: Splicing | R14: 29914 | S14: CO | T14: Splicer | U14: Male | V14: 80820 | W14: Other | X14: Single | Y14: Fully Meets | Z14: 3
A15: 3440 | B15: Xana | C15: Potts | D15: 43804 | E15: 44974 | F15: Area Sales Manager | G15: Gregory Walker | H15: xana.potts@bilearner.com | I15: CCDR | J15: Active | K15: Contract | L15: Zone A | M15: Full-Time | N15: Resignation | O15: Degree wish science when thing week old. | P15: Sales | Q15: Finance & Accounting | R15: 18938 | S15: KY | T15: Controller | U15: Female | V15: 40220 | W15: White | X15: Divorced | Y15: Fully Meets | Z15: 3
A16: 3441 | B16: Prater | C16: Jeremy | D16: 43583 | F16: Area Sales Manager | G16: Tyler Lewis | H16: prater.jeremy@bilearner.com | I16: BPC | J16: Active | K16: Part-Time | L16: Zone A | M16: Part-Time | N16: Unk | P16: Sales | Q16: General - Con | R16: 32833 | S16: NV | T16: Lineman | U16: Male | V16: 89139 | W16: Asian | X16: Widowed | Y16: Exceeds | Z16: 4
A17: 3442 | B17: Kaylah | C17: Moon | D17: 43655 | E17: 44728 | F17: Area Sales Manager | G17: Ashley Scott | H17: kaylah.moon@bilearner.com | I17: PYZ | J17: Active | K17: Full-Time | L17: Zone A | M17: Full-Time | N17: Retirement | O17: Fear particular method stage. | P17: IT/IS | Q17: Field Operations | R17: 19322 | S17: MA | T17: Laborer | U17: Male | V17: 2810 | W17: Black | X17: Single | Y17: Exceeds | Z17: 2
A18: 3443 | B18: Kristen | C18: Tate | D18: 44291 | E18: 45058 | F18: Area Sales Manager | G18: Lauren Jones | H18: kristen.tate@bilearner.com | I18: WBL | J18: Active | K18: Full-Time | L18: Zone C | M18: Part-Time | N18: Voluntary | O18: Wall body wonder successful. | P18: IT/IS | Q18: Project Management - Con | R18: 34432 | S18: KY | T18: Coordinator | U18: Male | V18: 2621 | W18: Asian | X18: Widowed | Y18: Fully Meets | Z18: 3
A19: 3444 | B19: Bobby | C19: Rodgers | D19: 44528 | E19: 44596 | F19: Area Sales Manager | G19: Matthew Jackson | H19: bobby.rodgers@bilearner.com | I19: NEL | J19: Active | K19: Contract | L19: Zone A | M19: Part-Time | N19: Voluntary | O19: Visit foot nearly radio treatment. | P19: Sales | Q19: Engineers | R19: 30635 | S19: KY | T19: Director | U19: Male | V19: 44553 | W19: Other | X19: Widowed | Y19: Fully Meets | Z19: 3
A20: 3445 | B20: Reid | C20: Park | D20: 44212 | F20: Area Sales Manager | G20: Michelle Mitchell | H20: reid.park@bilearner.com | I20: PL | J20: Active | K20: Contract | L20: Zone C | M20: Full-Time | N20: Unk | P20: Sales | Q20: Project Management - Con | R20: 31388 | S20: KY | T20: Supervisor | U20: Female | V20: 5360 | W20: Other | X20: Married | Y20: Exceeds | Z20: 4
A21: 3446 | B21: Hector | C21: Dalton | D21: 44432 | F21: Area Sales Manager | G21: Sydney French | H21: hector.dalton@bilearner.com | I21: BPC | J21: Active | K21: Part-Time | L21: Zone A | M21: Part-Time | N21: Unk | P21: Sales | Q21: Field Operations | R21: 35186 | S21: TX | T21: Driller | U21: Female | V21: 16325 | W21: White | X21: Divorced | Y21: Exceeds | Z21: 2
A22: 3447 | B22: Mariela | C22: Schultz | D22: 43977 | E22: 45095 | F22: Area Sales Manager | G22: Michelle Evans MD | H22: mariela.schultz@bilearner.com | I22: CCDR | J22: Future Start | K22: Part-Time | L22: Zone C | M22: Part-Time | N22: Involuntary | O22: Unit pass office southern break one. | P22: Sales | Q22: General - Con | R22: 23424 | S22: TX | T22: Technician | U22: Female | V22: 43481 | W22: Asian | X22: Widowed | Y22: Fully Meets | Z22: 3
A23: 3448 | B23: Angela | C23: Molina | D23: 43739 | E23: 44141 | F23: Area Sales Manager | G23: Patricia Cook | H23: angela.molina@bilearner.com | I23: SVG | J23: Future Start | K23: Full-Time | L23: Zone A | M23: Temporary | N23: Retirement | O23: List class mind. | P23: Sales | Q23: Engineers | R23: 21317 | S23: TX | T23: Specialist | U23: Male | V23: 50705 | W23: Asian | X23: Widowed | Y23: Fully Meets | Z23: 3
A24: 3449 | B24: Gerald | C24: Preston | D24: 45056 | E24: 45073 | F24: Area Sales Manager | G24: Ashley Reeves | H24: gerald.preston@bilearner.com | I24: EW | J24: Future Start | K24: Contract | L24: Zone B | M24: Temporary | N24: Involuntary | O24: Price third parent evening. | P24: Sales | Q24: General - Eng | R24: 33865 | S24: CO | T24: Technician | U24: Male | V24: 5168 | W24: Black | X24: Single | Y24: Fully Meets | Z24: 5
A25: 3450 | B25: Reilly | C25: Moyer | D25: 44075 | E25: 44899 | F25: Area Sales Manager | G25: Stanley Harvey | H25: reilly.moyer@bilearner.com | I25: MSC | J25: Active | K25: Contract | L25: Zone C | M25: Temporary | N25: Resignation | O25: Cause military a sense. Doctor property may. | P25: Sales | Q25: Field Operations | R25: 34557 | S25: CO | T25: Operator | U25: Male | V25: 11765 | W25: Other | X25: Single | Y25: Exceeds | Z25: 2
A26: 3451 | B26: Carlee | C26: French | D26: 44245 | E26: 44876 | F26: Area Sales Manager | G26: Michael Bradshaw | H26: carlee.french@bilearner.com | I26: TNS | J26: Active | K26: Contract | L26: Zone C | M26: Full-Time | N26: Voluntary | O26: Station another son positive. | P26: Sales | Q26: General - Con | R26: 24852 | S26: CO | T26: Technician | U26: Male | V26: 71071 | W26: Other | X26: Divorced | Y26: Exceeds | Z26: 3
A27: 3452 | B27: Jaydon | C27: Blackburn | D27: 44873 | F27: Area Sales Manager | G27: Debbie Crosby | H27: jaydon.blackburn@bilearner.com | I27: PYZ | J27: Active | K27: Part-Time | L27: Zone A | M27: Part-Time | N27: Unk | P27: Sales | Q27: General - Con | R27: 17174 | S27: IN | T27: Foreman | U27: Male | V27: 12122 | W27: Black | X27: Divorced | Y27: Fully Meets | Z27: 2
A28: 3453 | B28: Bridger | C28: Carter | D28: 44847 | F28: Area Sales Manager | G28: Elizabeth Taylor | H28: bridger.carter@bilearner.com | I28: WBL | J28: Active | K28: Contract | L28: Zone C | M28: Part-Time | N28: Unk | P28: Sales | Q28: Fielders | R28: 30048 | S28: MA | T28: Engineer | U28: Male | V28: 87065 | W28: White | X28: Widowed | Y28: Fully Meets | Z28: 4
A29: 3454 | B29: Leon | C29: Beard | D29: 44815 | F29: Area Sales Manager | G29: Brian Dunlap | H29: leon.beard@bilearner.com | I29: PYZ | J29: Active | K29: Full-Time | L29: Zone C | M29: Full-Time | N29: Unk | P29: IT/IS | Q29: General - Con | R29: 25597 | S29: KY | T29: Foreman | U29: Male | V29: 10415 | W29: Hispanic | X29: Married | Y29: Needs Improvement | Z29: 4
A30: 3455 | B30: Charity | C30: Miranda | D30: 44376 | E30: 44747 | F30: Area Sales Manager | G30: Daniel Rodriguez | H30: charity.miranda@bilearner.com | I30: WBL | J30: Active | K30: Full-Time | L30: Zone C | M30: Temporary | N30: Resignation | O30: Pm local take example fund. Small heavy listen. | P30: Sales | Q30: Project Management - Eng | R30: 36178 | S30: KY | T30: Manager | U30: Male | V30: 3763 | W30: Other | X30: Widowed | Y30: Exceeds | Z30: 4
A31: 3456 | B31: Axel | C31: Howe | D31: 44991 | F31: Area Sales Manager | G31: Martin Hammond | H31: axel.howe@bilearner.com | I31: NEL | J31: Active | K31: Full-Time | L31: Zone A | M31: Temporary | N31: Unk | P31: Sales | Q31: Field Operations | R31: 17070 | S31: KY | T31: Technician | U31: Female | V31: 79623 | W31: Black | X31: Divorced | Y31: Fully Meets | Z31: 3
A32: 3457 | B32: Milton | C32: Wall | D32: 44099 | F32: Area Sales Manager | G32: Sara Bell | H32: milton.wall@bilearner.com | I32: PL | J32: Active | K32: Full-Time | L32: Zone B | M32: Temporary | N32: Unk | P32: Sales | Q32: Engineers | R32: 17402 | S32: KY | T32: Technician | U32: Female | V32: 69189 | W32: White | X32: Divorced | Y32: Needs Improvement | Z32: 3
A33: 3458 | B33: Cory | C33: Robinson | D33: 44679 | E33: 45070 | F33: Area Sales Manager | G33: Elizabeth Anderson | H33: cory.robinson@bilearner.com | I33: BPC | J33: Future Start | K33: Contract | L33: Zone A | M33: Full-Time | N33: Voluntary | O33: Several young whether that expert. | P33: Sales | Q33: Field Operations | R33: 35289 | S33: TX | T33: Laborer | U33: Female | V33: 5194 | W33: Hispanic | X33: Single | Y33: Needs Improvement | Z33: 3
A34: 3459 | B34: Saniya | C34: Yu | D34: 44304 | E34: 44733 | F34: Area Sales Manager | G34: Erin Bailey | H34: saniya.yu@bilearner.com | I34: CCDR | J34: Future Start | K34: Part-Time | L34: Zone A | M34: Full-Time | N34: Retirement | O34: Science end approach democratic treatment. | P34: Sales | Q34: General - Con | R34: 16111 | S34: TX | T34: Splicer | U34: Male | V34: 8779 | W34: Black | X34: Widowed | Y34: Exceeds | Z34: 2
A35: 3460 | B35: Alisa | C35: James | D35: 43880 | F35: Area Sales Manager | G35: Dennis Henderson | H35: alisa.james@bilearner.com | I35: SVG | J35: Active | K35: Full-Time | L35: Zone A | M35: Full-Time | N35: Unk | P35: Sales | Q35: Aerial | R35: 16112 | S35: TX | T35: Lineman | U35: Male | V35: 74682 | W35: Asian | X35: Married | Y35: Fully Meets | Z35: 3
A36: 3461 | B36: Lincoln | C36: Compton | D36: 43664 | E36: 44470 | F36: Area Sales Manager | G36: Tammy Conner | H36: lincoln.compton@bilearner.com | I36: EW | J36: Future Start | K36: Full-Time | L36: Zone C | M36: Part-Time | N36: Resignation | O36: Base scene central unit per argue. Might last of. | P36: Sales | Q36: General - Con | R36: 35793 | S36: CO | T36: Foreman | U36: Male | V36: 78046 | W36: Hispanic | X36: Married | Y36: Needs Improvement | Z36: 1
A37: 3462 | B37: Aliana | C37: Nolan | D37: 43356 | E37: 44456 | F37: Area Sales Manager | G37: Brianna Mathews | H37: aliana.nolan@bilearner.com | I37: MSC | J37: Active | K37: Contract | L37: Zone A | M37: Full-Time | N37: Involuntary | O37: Yourself book budget product. | P37: Sales | Q37: Field Operations | R37: 15562 | S37: CO | T37: Coordinator | U37: Male | V37: 27270 | W37: Hispanic | X37: Divorced | Y37: Needs Improvement | Z37: 3
A38: 3463 | B38: Kayden | C38: Dodson | D38: 43951 | E38: 44395 | F38: Area Sales Manager | G38: Jessica Peters | H38: kayden.dodson@bilearner.com | I38: TNS | J38: Active | K38: Part-Time | L38: Zone A | M38: Temporary | N38: Retirement | O38: Paper can score else investment. | P38: Sales | Q38: Field Operations | R38: 18800 | S38: IN | T38: Tower Hand | U38: Male | V38: 12703 | W38: Hispanic | X38: Single | Y38: Fully Meets | Z38: 1
A39: 3464 | B39: James | C39: Duke | D39: 43437 | E39: 44813 | F39: Area Sales Manager | G39: Mark Harris | H39: james.duke@bilearner.com | I39: PYZ | J39: Active | K39: Contract | L39: Zone B | M39: Full-Time | N39: Involuntary | O39: Stuff different color how. | P39: Sales | Q39: Shop (Fleet) | R39: 35963 | S39: MA | T39: Mechanic | U39: Male | V39: 66835 | W39: Black | X39: Widowed | Y39: Needs Improvement | Z39: 5
A40: 3465 | B40: Willow | C40: Stuart | D40: 44508 | F40: Area Sales Manager | G40: Elizabeth Tapia | H40: willow.stuart@bilearner.com | I40: WBL | J40: Active | K40: Full-Time | L40: Zone B | M40: Full-Time | N40: Unk | P40: Sales | Q40: General - Con | R40: 22653 | S40: MA | T40: Flagger | U40: Male | V40: 66150 | W40: Asian | X40: Divorced | Y40: Needs Improvement | Z40: 3
...

Sheet Revisi Data
A1: EmpID | B1: FirstName | C1: LastName | D1: StartDate | E1: ExitDate | F1: Title | G1: Supervisor | H1: ADEmail | I1: BusinessUnit | J1: EmployeeStatus | K1: EmployeeType | L1: PayZone | M1: EmployeeClassificationType | N1: TerminationType | O1: TerminationDescription | P1: DepartmentType | Q1: Division | R1: DOB | S1: State | T1: JobFunctionDescription | U1: GenderCode | V1: LocationCode | W1: RaceDesc | X1: MaritalDesc | Y1: Performance Score | Z1: Current Employee Rating
A2: =TRIM(employee_data!A2) -> 3427 | B2: =TRIM(PROPER(employee_data!B2)) -> Uriah | C2: =TRIM(PROPER(employee_data!C2)) -> Bridges | D2: =DATEVALUE(TEXT(employee_data!D2,"dd/mm/yyyy")) -> 43728 | E2: =IFERROR(DATEVALUE(TEXT(employee_data!E2,"dd/mm/yyyy")),TRIM("")) | F2: =TRIM(employee_data!F2) -> Production Technician I | G2: =TRIM(PROPER(employee_data!G2)) -> Peter Oneill | H2: =TRIM(employee_data!H2) -> uriah.bridges@bilearner.com | I2: =TRIM(UPPER(employee_data!I2)) -> CCDR | J2: =TRIM(PROPER(employee_data!J2)) -> Active | K2: =TRIM(PROPER(employee_data!K2)) -> Contract | L2: =TRIM(PROPER(employee_data!L2)) -> Zone C | M2: =TRIM(PROPER(employee_data!M2)) -> Temporary | N2: =TRIM(PROPER(employee_data!N2)) -> Unk | O2: =TRIM(employee_data!O2) | P2: =TRIM(PROPER(employee_data!P2)) -> Production | Q2: =TRIM(PROPER(employee_data!Q2)) -> Finance & Accounting | R2: =DATEVALUE(TEXT(employee_data!R2,"dd/mm/yyyy")) -> 25483 | S2: =TRIM(UPPER(employee_data!S2)) -> MA | T2: =TRIM(PROPER(employee_data!T2)) -> Accounting | U2: =TRIM(PROPER(employee_data!U2)) -> Female | V2: =TRIM(employee_data!V2) -> 34904 | W2: =TRIM(PROPER(employee_data!W2)) -> White | X2: =TRIM(PROPER(employee_data!X2)) -> Widowed | Y2: =TRIM(PROPER(employee_data!Y2)) -> Fully Meets | Z2: 4
A3: =TRIM(employee_data!A3) -> 3428 | B3: =TRIM(PROPER(employee_data!B3)) -> Paula | C3: =TRIM(PROPER(employee_data!C3)) -> Small | D3: =DATEVALUE(TEXT(employee_data!D3,"dd/mm/yyyy")) -> 44968 | E3: =IFERROR(DATEVALUE(TEXT(employee_data!E3,"dd/mm/yyyy")),TRIM("")) | F3: =TRIM(employee_data!F3) -> Production Technician I | G3: =TRIM(PROPER(employee_data!G3)) -> Renee Mccormick | H3: =TRIM(employee_data!H3) -> paula.small@bilearner.com | I3: =TRIM(UPPER(employee_data!I3)) -> EW | J3: =TRIM(PROPER(employee_data!J3)) -> Active | K3: =TRIM(PROPER(employee_data!K3)) -> Contract | L3: =TRIM(PROPER(employee_data!L3)) -> Zone A | M3: =TRIM(PROPER(employee_data!M3)) -> Part-Time | N3: =TRIM(PROPER(employee_data!N3)) -> Unk | O3: =TRIM(employee_data!O3) | P3: =TRIM(PROPER(employee_data!P3)) -> Production | Q3: =TRIM(PROPER(employee_data!Q3)) -> Aerial | R3: =DATEVALUE(TEXT(employee_data!R3,"dd/mm/yyyy")) -> 23984 | S3: =TRIM(UPPER(employee_data!S3)) -> MA | T3: =TRIM(PROPER(employee_data!T3)) -> Labor | U3: =TRIM(PROPER(employee_data!U3)) -> Male | V3: =TRIM(employee_data!V3) -> 6593 | W3: =TRIM(PROPER(employee_data!W3)) -> Hispanic | X3: =TRIM(PROPER(employee_data!X3)) -> Widowed | Y3: =TRIM(PROPER(employee_data!Y3)) -> Fully Meets | Z3: 3
A4: =TRIM(employee_data!A4) -> 3429 | B4: =TRIM(PROPER(employee_data!B4)) -> Edward | C4: =TRIM(PROPER(employee_data!C4)) -> Buck | D4: =DATEVALUE(TEXT(employee_data!D4,"dd/mm/yyyy")) -> 43444 | E4: =IFERROR(DATEVALUE(TEXT(employee_data!E4,"dd/mm/yyyy")),TRIM("")) | F4: =TRIM(employee_data!F4) -> Area Sales Manager | G4: =TRIM(PROPER(employee_data!G4)) -> Crystal Walker | H4: =TRIM(employee_data!H4) -> edward.buck@bilearner.com | I4: =TRIM(UPPER(employee_data!I4)) -> PL | J4: =TRIM(PROPER(employee_data!J4)) -> Active | K4: =TRIM(PROPER(employee_data!K4)) -> Full-Time | L4: =TRIM(PROPER(employee_data!L4)) -> Zone B | M4: =TRIM(PROPER(employee_data!M4)) -> Part-Time | N4: =TRIM(PROPER(employee_data!N4)) -> Unk | O4: =TRIM(employee_data!O4) | P4: =TRIM(PROPER(employee_data!P4)) -> Sales | Q4: =TRIM(PROPER(employee_data!Q4)) -> General - Sga | R4: =DATEVALUE(TEXT(employee_data!R4,"dd/mm/yyyy")) -> 33517 | S4: =TRIM(UPPER(employee_data!S4)) -> MA | T4: =TRIM(PROPER(employee_data!T4)) -> Assistant | U4: =TRIM(PROPER(employee_data!U4)) -> Male | V4: =TRIM(employee_data!V4) -> 2330 | W4: =TRIM(PROPER(employee_data!W4)) -> Hispanic | X4: =TRIM(PROPER(employee_data!X4)) -> Widowed | Y4: =TRIM(PROPER(employee_data!Y4)) -> Fully Meets | Z4: 4
A5: =TRIM(employee_data!A5) -> 3430 | B5: =TRIM(PROPER(employee_data!B5)) -> Michael | C5: =TRIM(PROPER(employee_data!C5)) -> Riordan | D5: =DATEVALUE(TEXT(employee_data!D5,"dd/mm/yyyy")) -> 44368 | E5: =IFERROR(DATEVALUE(TEXT(employee_data!E5,"dd/mm/yyyy")),TRIM("")) | F5: =TRIM(employee_data!F5) -> Area Sales Manager | G5: =TRIM(PROPER(employee_data!G5)) -> Rebekah Wright | H5: =TRIM(employee_data!H5) -> michael.riordan@bilearner.com | I5: =TRIM(UPPER(employee_data!I5)) -> CCDR | J5: =TRIM(PROPER(employee_data!J5)) -> Active | K5: =TRIM(PROPER(employee_data!K5)) -> Contract | L5: =TRIM(PROPER(employee_data!L5)) -> Zone A | M5: =TRIM(PROPER(employee_data!M5)) -> Full-Time | N5: =TRIM(PROPER(employee_data!N5)) -> Unk | O5: =TRIM(employee_data!O5) | P5: =TRIM(PROPER(employee_data!P5)) -> Sales | Q5: =TRIM(PROPER(employee_data!Q5)) -> Finance & Accounting | R5: =DATEVALUE(TEXT(employee_data!R5,"dd/mm/yyyy")) -> 35889 | S5: =TRIM(UPPER(employee_data!S5)) -> ND | T5: =TRIM(PROPER(employee_data!T5)) -> Clerk | U5: =TRIM(PROPER(employee_data!U5)) -> Male | V5: =TRIM(employee_data!V5) -> 58782 | W5: =TRIM(PROPER(employee_data!W5)) -> Other | X5: =TRIM(PROPER(employee_data!X5)) -> Single | Y5: =TRIM(PROPER(employee_data!Y5)) -> Fully Meets | Z5: 2
A6: =TRIM(employee_data!A6) -> 3431 | B6: =TRIM(PROPER(employee_data!B6)) -> Jasmine | C6: =TRIM(PROPER(employee_data!C6)) -> Onque | D6: =DATEVALUE(TEXT(employee_data!D6,"dd/mm/yyyy")) -> 43645 | E6: =IFERROR(DATEVALUE(TEXT(employee_data!E6,"dd/mm/yyyy")),TRIM("")) | F6: =TRIM(employee_data!F6) -> Area Sales Manager | G6: =TRIM(PROPER(employee_data!G6)) -> Jason Kim | H6: =TRIM(employee_data!H6) -> jasmine.onque@bilearner.com | I6: =TRIM(UPPER(employee_data!I6)) -> TNS | J6: =TRIM(PROPER(employee_data!J6)) -> Active | K6: =TRIM(PROPER(employee_data!K6)) -> Contract | L6: =TRIM(PROPER(employee_data!L6)) -> Zone A | M6: =TRIM(PROPER(employee_data!M6)) -> Temporary | N6: =TRIM(PROPER(employee_data!N6)) -> Unk | O6: =TRIM(employee_data!O6) | P6: =TRIM(PROPER(employee_data!P6)) -> Sales | Q6: =TRIM(PROPER(employee_data!Q6)) -> General - Con | R6: =DATEVALUE(TEXT(employee_data!R6,"dd/mm/yyyy")) -> 25444 | S6: =TRIM(UPPER(employee_data!S6)) -> FL | T6: =TRIM(PROPER(employee_data!T6)) -> Laborer | U6: =TRIM(PROPER(employee_data!U6)) -> Female | V6: =TRIM(employee_data!V6) -> 33174 | W6: =TRIM(PROPER(employee_data!W6)) -> Other | X6: =TRIM(PROPER(employee_data!X6)) -> Married | Y6: =TRIM(PROPER(employee_data!Y6)) -> Fully Meets | Z6: 3
A7: =TRIM(employee_data!A7) -> 3432 | B7: =TRIM(PROPER(employee_data!B7)) -> Maruk | C7: =TRIM(PROPER(employee_data!C7)) -> Fraval | D7: =DATEVALUE(TEXT(employee_data!D7,"dd/mm/yyyy")) -> 43847 | E7: =IFERROR(DATEVALUE(TEXT(employee_data!E7,"dd/mm/yyyy")),TRIM("")) | F7: =TRIM(employee_data!F7) -> Area Sales Manager | G7: =TRIM(PROPER(employee_data!G7)) -> Sheri Campos | H7: =TRIM(employee_data!H7) -> maruk.fraval@bilearner.com | I7: =TRIM(UPPER(employee_data!I7)) -> BPC | J7: =TRIM(PROPER(employee_data!J7)) -> Active | K7: =TRIM(PROPER(employee_data!K7)) -> Contract | L7: =TRIM(PROPER(employee_data!L7)) -> Zone B | M7: =TRIM(PROPER(employee_data!M7)) -> Full-Time | N7: =TRIM(PROPER(employee_data!N7)) -> Unk | O7: =TRIM(employee_data!O7) | P7: =TRIM(PROPER(employee_data!P7)) -> Sales | Q7: =TRIM(PROPER(employee_data!Q7)) -> Field Operations | R7: =DATEVALUE(TEXT(employee_data!R7,"dd/mm/yyyy")) -> 17991 | S7: =TRIM(UPPER(employee_data!S7)) -> CT | T7: =TRIM(PROPER(employee_data!T7)) -> Driver | U7: =TRIM(PROPER(employee_data!U7)) -> Male | V7: =TRIM(employee_data!V7) -> 6050 | W7: =TRIM(PROPER(employee_data!W7)) -> Black | X7: =TRIM(PROPER(employee_data!X7)) -> Married | Y7: =TRIM(PROPER(employee_data!Y7)) -> Fully Meets | Z7: 3
A8: =TRIM(employee_data!A8) -> 3433 | B8: =TRIM(PROPER(employee_data!B8)) -> Latia | C8: =TRIM(PROPER(employee_data!C8)) -> Costa | D8: =DATEVALUE(TEXT(employee_data!D8,"dd/mm/yyyy")) -> 44657 | E8: =IFERROR(DATEVALUE(TEXT(employee_data!E8,"dd/mm/yyyy")),TRIM("")) -> 45110 | F8: =TRIM(employee_data!F8) -> Area Sales Manager | G8: =TRIM(PROPER(employee_data!G8)) -> Jacob Braun | H8: =TRIM(employee_data!H8) -> latia.costa@bilearner.com | I8: =TRIM(UPPER(employee_data!I8)) -> WBL | J8: =TRIM(PROPER(employee_data!J8)) -> Active | K8: =TRIM(PROPER(employee_data!K8)) -> Full-Time | L8: =TRIM(PROPER(employee_data!L8)) -> Zone B | M8: =TRIM(PROPER(employee_data!M8)) -> Temporary | N8: =TRIM(PROPER(employee_data!N8)) -> Involuntary | O8: =TRIM(employee_data!O8) -> Me see picture nature degree benefit. | P8: =TRIM(PROPER(employee_data!P8)) -> Sales | Q8: =TRIM(PROPER(employee_data!Q8)) -> General - Eng | R8: =DATEVALUE(TEXT(employee_data!R8,"dd/mm/yyyy")) -> 15523 | S8: =TRIM(UPPER(employee_data!S8)) -> CA | T8: =TRIM(PROPER(employee_data!T8)) -> Technician | U8: =TRIM(PROPER(employee_data!U8)) -> Female | V8: =TRIM(employee_data!V8) -> 90007 | W8: =TRIM(PROPER(employee_data!W8)) -> Hispanic | X8: =TRIM(PROPER(employee_data!X8)) -> Divorced | Y8: =TRIM(PROPER(employee_data!Y8)) -> Exceeds | Z8: 4
A9: =TRIM(employee_data!A9) -> 3434 | B9: =TRIM(PROPER(employee_data!B9)) -> Sharlene | C9: =TRIM(PROPER(employee_data!C9)) -> Terry | D9: =DATEVALUE(TEXT(employee_data!D9,"dd/mm/yyyy")) -> 44141 | E9: =IFERROR(DATEVALUE(TEXT(employee_data!E9,"dd/mm/yyyy")),TRIM("")) -> 44955 | F9: =TRIM(employee_data!F9) -> Area Sales Manager | G9: =TRIM(PROPER(employee_data!G9)) -> Tracy Marquez | H9: =TRIM(employee_data!H9) -> sharlene.terry@bilearner.com | I9: =TRIM(UPPER(employee_data!I9)) -> CCDR | J9: =TRIM(PROPER(employee_data!J9)) -> Active | K9: =TRIM(PROPER(employee_data!K9)) -> Contract | L9: =TRIM(PROPER(employee_data!L9)) -> Zone C | M9: =TRIM(PROPER(employee_data!M9)) -> Full-Time | N9: =TRIM(PROPER(employee_data!N9)) -> Involuntary | O9: =TRIM(employee_data!O9) -> Blue community type skill story. | P9: =TRIM(PROPER(employee_data!P9)) -> Sales | Q9: =TRIM(PROPER(employee_data!Q9)) -> Engineers | R9: =DATEVALUE(TEXT(employee_data!R9,"dd/mm/yyyy")) -> 20886 | S9: =TRIM(UPPER(employee_data!S9)) -> OR | T9: =TRIM(PROPER(employee_data!T9)) -> Engineer | U9: =TRIM(PROPER(employee_data!U9)) -> Female | V9: =TRIM(employee_data!V9) -> 97756 | W9: =TRIM(PROPER(employee_data!W9)) -> White | X9: =TRIM(PROPER(employee_data!X9)) -> Divorced | Y9: =TRIM(PROPER(employee_data!Y9)) -> Fully Meets | Z9: 2
A10: =TRIM(employee_data!A10) -> 3435 | B10: =TRIM(PROPER(employee_data!B10)) -> Jac | C10: =TRIM(PROPER(employee_data!C10)) -> Mckinzie | D10: =DATEVALUE(TEXT(employee_data!D10,"dd/mm/yyyy")) -> 43330 | E10: =IFERROR(DATEVALUE(TEXT(employee_data!E10,"dd/mm/yyyy")),TRIM("")) | F10: =TRIM(employee_data!F10) -> Area Sales Manager | G10: =TRIM(PROPER(employee_data!G10)) -> Sharon Becker | H10: =TRIM(employee_data!H10) -> jac.mckinzie@bilearner.com | I10: =TRIM(UPPER(employee_data!I10)) -> NEL | J10: =TRIM(PROPER(employee_data!J10)) -> Active | K10: =TRIM(PROPER(employee_data!K10)) -> Contract | L10: =TRIM(PROPER(employee_data!L10)) -> Zone B | M10: =TRIM(PROPER(employee_data!M10)) -> Part-Time | N10: =TRIM(PROPER(employee_data!N10)) -> Unk | O10: =TRIM(employee_data!O10) | P10: =TRIM(PROPER(employee_data!P10)) -> Sales | Q10: =TRIM(PROPER(employee_data!Q10)) -> Executive | R10: =DATEVALUE(TEXT(employee_data!R10,"dd/mm/yyyy")) -> 27164 | S10: =TRIM(UPPER(employee_data!S10)) -> TX | T10: =TRIM(PROPER(employee_data!T10)) -> Executive Assistant | U10: =TRIM(PROPER(employee_data!U10)) -> Male | V10: =TRIM(employee_data!V10) -> 78789 | W10: =TRIM(PROPER(employee_data!W10)) -> Black | X10: =TRIM(PROPER(employee_data!X10)) -> Widowed | Y10: =TRIM(PROPER(employee_data!Y10)) -> Exceeds | Z10: 3
A11: =TRIM(employee_data!A11) -> 3436 | B11: =TRIM(PROPER(employee_data!B11)) -> Joseph | C11: =TRIM(PROPER(employee_data!C11)) -> Martins | D11: =DATEVALUE(TEXT(employee_data!D11,"dd/mm/yyyy")) -> 44582 | E11: =IFERROR(DATEVALUE(TEXT(employee_data!E11,"dd/mm/yyyy")),TRIM("")) -> 45106 | F11: =TRIM(employee_data!F11) -> Area Sales Manager | G11: =TRIM(PROPER(employee_data!G11)) -> George Jenkins | H11: =TRIM(employee_data!H11) -> joseph.martins@bilearner.com | I11: =TRIM(UPPER(employee_data!I11)) -> BPC | J11: =TRIM(PROPER(employee_data!J11)) -> Active | K11: =TRIM(PROPER(employee_data!K11)) -> Part-Time | L11: =TRIM(PROPER(employee_data!L11)) -> Zone B | M11: =TRIM(PROPER(employee_data!M11)) -> Temporary | N11: =TRIM(PROPER(employee_data!N11)) -> Resignation | O11: =TRIM(employee_data!O11) -> Summer personal bag. | P11: =TRIM(PROPER(employee_data!P11)) -> Sales | Q11: =TRIM(PROPER(employee_data!Q11)) -> Engineers | R11: =DATEVALUE(TEXT(employee_data!R11,"dd/mm/yyyy")) -> 18213 | S11: =TRIM(UPPER(employee_data!S11)) -> TX | T11: =TRIM(PROPER(employee_data!T11)) -> Engineer | U11: =TRIM(PROPER(employee_data!U11)) -> Male | V11: =TRIM(employee_data!V11) -> 78207 | W11: =TRIM(PROPER(employee_data!W11)) -> Asian | X11: =TRIM(PROPER(employee_data!X11)) -> Widowed | Y11: =TRIM(PROPER(employee_data!Y11)) -> Fully Meets | Z11: 5
A12: =TRIM(employee_data!A12) -> 3437 | B12: =TRIM(PROPER(employee_data!B12)) -> Myriam | C12: =TRIM(PROPER(employee_data!C12)) -> Givens | D12: =DATEVALUE(TEXT(employee_data!D12,"dd/mm/yyyy")) -> 45142 | E12: =IFERROR(DATEVALUE(TEXT(employee_data!E12,"dd/mm/yyyy")),TRIM("")) | F12: =TRIM(employee_data!F12) -> Area Sales Manager | G12: =TRIM(PROPER(employee_data!G12)) -> Troy White | H12: =TRIM(employee_data!H12) -> myriam.givens@bilearner.com | I12: =TRIM(UPPER(employee_data!I12)) -> SVG | J12: =TRIM(PROPER(employee_data!J12)) -> Active | K12: =TRIM(PROPER(employee_data!K12)) -> Contract | L12: =TRIM(PROPER(employee_data!L12)) -> Zone B | M12: =TRIM(PROPER(employee_data!M12)) -> Temporary | N12: =TRIM(PROPER(employee_data!N12)) -> Unk | O12: =TRIM(employee_data!O12) | P12: =TRIM(PROPER(employee_data!P12)) -> Sales | Q12: =TRIM(PROPER(employee_data!Q12)) -> Field Operations | R12: =DATEVALUE(TEXT(employee_data!R12,"dd/mm/yyyy")) -> 23402 | S12: =TRIM(UPPER(employee_data!S12)) -> IN | T12: =TRIM(PROPER(employee_data!T12)) -> Technician | U12: =TRIM(PROPER(employee_data!U12)) -> Female | V12: =TRIM(employee_data!V12) -> 46204 | W12: =TRIM(PROPER(employee_data!W12)) -> Other | X12: =TRIM(PROPER(employee_data!X12)) -> Single | Y12: =TRIM(PROPER(employee_data!Y12)) -> Fully Meets | Z12: 5
A13: =TRIM(employee_data!A13) -> 3438 | B13: =TRIM(PROPER(employee_data!B13)) -> Dheepa | C13: =TRIM(PROPER(employee_data!C13)) -> Nguyen | D13: =DATEVALUE(TEXT(employee_data!D13,"dd/mm/yyyy")) -> 43322 | E13: =IFERROR(DATEVALUE(TEXT(employee_data!E13,"dd/mm/yyyy")),TRIM("")) -> 43773 | F13: =TRIM(employee_data!F13) -> Area Sales Manager | G13: =TRIM(PROPER(employee_data!G13)) -> Brian Miller | H13: =TRIM(employee_data!H13) -> dheepa.nguyen@bilearner.com | I13: =TRIM(UPPER(employee_data!I13)) -> MSC | J13: =TRIM(PROPER(employee_data!J13)) -> Active | K13: =TRIM(PROPER(employee_data!K13)) -> Full-Time | L13: =TRIM(PROPER(employee_data!L13)) -> Zone C | M13: =TRIM(PROPER(employee_data!M13)) -> Temporary | N13: =TRIM(PROPER(employee_data!N13)) -> Retirement | O13: =TRIM(employee_data!O13) -> Alone once than. More condition pay far. | P13: =TRIM(PROPER(employee_data!P13)) -> Sales | Q13: =TRIM(PROPER(employee_data!Q13)) -> General - Con | R13: =DATEVALUE(TEXT(employee_data!R13,"dd/mm/yyyy")) -> 17629 | S13: =TRIM(UPPER(employee_data!S13)) -> GA | T13: =TRIM(PROPER(employee_data!T13)) -> Technician | U13: =TRIM(PROPER(employee_data!U13)) -> Female | V13: =TRIM(employee_data!V13) -> 30428 | W13: =TRIM(PROPER(employee_data!W13)) -> Asian | X13: =TRIM(PROPER(employee_data!X13)) -> Married | Y13: =TRIM(PROPER(employee_data!Y13)) -> Fully Meets | Z13: 3
... A3001: =TRIM(employee_data!A3001) -> 3426 | B3001: =TRIM(PROPER(employee_data!B3001)) -> Chace | C3001: =TRIM(PROPER(employee_data!C3001)) -> Kerr | D3001: =DATEVALUE(TEXT(employee_data!D3001,"dd/mm/yyyy")) -> 44678 | E3001: =IFERROR(DATEVALUE(TEXT(employee_data!E3001,"dd/mm/yyyy")),TRIM("")) | F3001: =TRIM(employee_data!F3001) -> Production Technician I | G3001: =TRIM(PROPER(employee_data!G3001)) -> Javier Mccall | H3001: =TRIM(employee_data!H3001) -> chace.kerr@bilearner.com | I3001: =TRIM(UPPER(employee_data!I3001)) -> BPC | J3001: =TRIM(PROPER(employee_data!J3001)) -> Active | K3001: =TRIM(PROPER(employee_data!K3001)) -> Full-Time | L3001: =TRIM(PROPER(employee_data!L3001)) -> Zone B | M3001: =TRIM(PROPER(employee_data!M3001)) -> Temporary | N3001: =TRIM(PROPER(employee_data!N3001)) -> Unk | O3001: =TRIM(employee_data!O3001) | P3001: =TRIM(PROPER(employee_data!P3001)) -> Production | Q3001: =TRIM(PROPER(employee_data!Q3001)) -> Field Operations | R3001: =DATEVALUE(TEXT(employee_data!R3001,"dd/mm/yyyy")) -> 33127 | S3001: =TRIM(UPPER(employee_data!S3001)) -> MA | T3001: =TRIM(PROPER(employee_data!T3001)) -> Warehouse Technician | U3001: =TRIM(PROPER(employee_data!U3001)) -> Female | V3001: =TRIM(employee_data!V3001) -> 57487 | W3001: =TRIM(PROPER(employee_data!W3001)) -> White | X3001: =TRIM(PROPER(employee_data!X3001)) -> Married | Y3001: =TRIM(PROPER(employee_data!Y3001)) -> Fully Meets | Z3001: 2

Sheet  FIX DATA PIVOT
A1: EmpID | B1: FirstName | C1: LastName | D1: StartDate | E1: ExitDate | F1: Title | G1: Supervisor | H1: ADEmail | I1: BusinessUnit | J1: EmployeeStatus | K1: EmployeeType | L1: PayZone | M1: EmployeeClassificationType | N1: TerminationType | O1: TerminationDescription | P1: DepartmentType | Q1: Division | R1: DOB | S1: State | T1: JobFunctionDescription | U1: GenderCode | V1: LocationCode | W1: RaceDesc | X1: MaritalDesc | Y1: Performance Score | Z1: Current Employee Rating | AA1: CurrentEmployeeStatus | AB1: Year of Birth | AC1: Umur | AD1: Generasi
A2: 3427 | B2: Uriah | C2: Bridges | D2: 43728 | F2: Production Technician I | G2: Peter Oneill | H2: uriah.bridges@bilearner.com | I2: CCDR | J2: Active | K2: Contract | L2: Zone C | M2: Temporary | N2: Unk | P2: Production | Q2: Finance & Accounting | R2: 25483 | S2: MA | T2: Accounting | U2: Female | V2: 34904 | W2: White | X2: Widowed | Y2: Fully Meets | Z2: 4 | AA2: =IF(E2="","Active","Non-Active") -> Active | AB2: =YEAR(R2) -> 1969 | AC2: =INT(YEARFRAC(R2,"20/04/2026")) -> 56 | AD2: {=_xlfn.IFS(AB2<1965,"Baby Boomers",AB2<1981,"Gen X",AB2<1997,"Millenial",TRUE,("Gen Z"))} -> Gen X
A3: 3428 | B3: Paula | C3: Small | D3: 44968 | F3: Production Technician I | G3: Renee Mccormick | H3: paula.small@bilearner.com | I3: EW | J3: Active | K3: Contract | L3: Zone A | M3: Part-Time | N3: Unk | P3: Production | Q3: Aerial | R3: 23984 | S3: MA | T3: Labor | U3: Male | V3: 6593 | W3: Hispanic | X3: Widowed | Y3: Fully Meets | Z3: 3 | AA3: =IF(E3="","Active","Non-Active") -> Active | AB3: =YEAR(R3) -> 1965 | AC3: =INT(YEARFRAC(R3,"20/04/2026")) -> 60 | AD3: {=_xlfn.IFS(AB3<1965,"Baby Boomers",AB3<1981,"Gen X",AB3<1997,"Millenial",TRUE,("Gen Z"))} -> Gen X | AF3: Formula COUNTIFS untuk menentukan jumlah karyawan yang mendapatkan rating
A4: 3429 | B4: Edward | C4: Buck | D4: 43444 | F4: Area Sales Manager | G4: Crystal Walker | H4: edward.buck@bilearner.com | I4: PL | J4: Active | K4: Full-Time | L4: Zone B | M4: Part-Time | N4: Unk | P4: Sales | Q4: General - Sga | R4: 33517 | S4: MA | T4: Assistant | U4: Male | V4: 2330 | W4: Hispanic | X4: Widowed | Y4: Fully Meets | Z4: 4 | AA4: =IF(E4="","Active","Non-Active") -> Active | AB4: =YEAR(R4) -> 1991 | AC4: =INT(YEARFRAC(R4,"20/04/2026")) -> 34 | AD4: {=_xlfn.IFS(AB4<1965,"Baby Boomers",AB4<1981,"Gen X",AB4<1997,"Millenial",TRUE,("Gen Z"))} -> Millenial
A5: 3430 | B5: Michael | C5: Riordan | D5: 44368 | F5: Area Sales Manager | G5: Rebekah Wright | H5: michael.riordan@bilearner.com | I5: CCDR | J5: Active | K5: Contract | L5: Zone A | M5: Full-Time | N5: Unk | P5: Sales | Q5: Finance & Accounting | R5: 35889 | S5: ND | T5: Clerk | U5: Male | V5: 58782 | W5: Other | X5: Single | Y5: Fully Meets | Z5: 2 | AA5: =IF(E5="","Active","Non-Active") -> Active | AB5: =YEAR(R5) -> 1998 | AC5: =INT(YEARFRAC(R5,"20/04/2026")) -> 28 | AD5: {=_xlfn.IFS(AB5<1965,"Baby Boomers",AB5<1981,"Gen X",AB5<1997,"Millenial",TRUE,("Gen Z"))} -> Gen Z | AF5: Rating | AG5: Jumlah
A6: 3431 | B6: Jasmine | C6: Onque | D6: 43645 | F6: Area Sales Manager | G6: Jason Kim | H6: jasmine.onque@bilearner.com | I6: TNS | J6: Active | K6: Contract | L6: Zone A | M6: Temporary | N6: Unk | P6: Sales | Q6: General - Con | R6: 25444 | S6: FL | T6: Laborer | U6: Female | V6: 33174 | W6: Other | X6: Married | Y6: Fully Meets | Z6: 3 | AA6: =IF(E6="","Active","Non-Active") -> Active | AB6: =YEAR(R6) -> 1969 | AC6: =INT(YEARFRAC(R6,"20/04/2026")) -> 56 | AD6: {=_xlfn.IFS(AB6<1965,"Baby Boomers",AB6<1981,"Gen X",AB6<1997,"Millenial",TRUE,("Gen Z"))} -> Gen X | AF6: {=_xlfn.UNIQUE(Table1[Current Employee Rating])} -> 4 | AG6: =COUNTIF(Table1[Current Employee Rating],"4") -> 419
A7: 3432 | B7: Maruk | C7: Fraval | D7: 43847 | F7: Area Sales Manager | G7: Sheri Campos | H7: maruk.fraval@bilearner.com | I7: BPC | J7: Active | K7: Contract | L7: Zone B | M7: Full-Time | N7: Unk | P7: Sales | Q7: Field Operations | R7: 17991 | S7: CT | T7: Driver | U7: Male | V7: 6050 | W7: Black | X7: Married | Y7: Fully Meets | Z7: 3 | AA7: =IF(E7="","Active","Non-Active") -> Active | AB7: =YEAR(R7) -> 1949 | AC7: =INT(YEARFRAC(R7,"20/04/2026")) -> 77 | AD7: {=_xlfn.IFS(AB7<1965,"Baby Boomers",AB7<1981,"Gen X",AB7<1997,"Millenial",TRUE,("Gen Z"))} -> Baby Boomers | AF7: 3 | AG7: =COUNTIF(Table1[Current Employee Rating],"3") -> 1530
A8: 3433 | B8: Latia | C8: Costa | D8: 44657 | E8: 45110 | F8: Area Sales Manager | G8: Jacob Braun | H8: latia.costa@bilearner.com | I8: WBL | J8: Active | K8: Full-Time | L8: Zone B | M8: Temporary | N8: Involuntary | O8: Me see picture nature degree benefit. | P8: Sales | Q8: General - Eng | R8: 15523 | S8: CA | T8: Technician | U8: Female | V8: 90007 | W8: Hispanic | X8: Divorced | Y8: Exceeds | Z8: 4 | AA8: =IF(E8="","Active","Non-Active") -> Non-Active | AB8: =YEAR(R8) -> 1942 | AC8: =INT(YEARFRAC(R8,"20/04/2026")) -> 83 | AD8: {=_xlfn.IFS(AB8<1965,"Baby Boomers",AB8<1981,"Gen X",AB8<1997,"Millenial",TRUE,("Gen Z"))} -> Baby Boomers | AF8: 2 | AG8: =COUNTIF(Table1[Current Employee Rating],"2") -> 510
A9: 3434 | B9: Sharlene | C9: Terry | D9: 44141 | E9: 44955 | F9: Area Sales Manager | G9: Tracy Marquez | H9: sharlene.terry@bilearner.com | I9: CCDR | J9: Active | K9: Contract | L9: Zone C | M9: Full-Time | N9: Involuntary | O9: Blue community type skill story. | P9: Sales | Q9: Engineers | R9: 20886 | S9: OR | T9: Engineer | U9: Female | V9: 97756 | W9: White | X9: Divorced | Y9: Fully Meets | Z9: 2 | AA9: =IF(E9="","Active","Non-Active") -> Non-Active | AB9: =YEAR(R9) -> 1957 | AC9: =INT(YEARFRAC(R9,"20/04/2026")) -> 69 | AD9: {=_xlfn.IFS(AB9<1965,"Baby Boomers",AB9<1981,"Gen X",AB9<1997,"Millenial",TRUE,("Gen Z"))} -> Baby Boomers | AF9: 5 | AG9: =COUNTIF(Table1[Current Employee Rating],"5") -> 270
A10: 3435 | B10: Jac | C10: Mckinzie | D10: 43330 | F10: Area Sales Manager | G10: Sharon Becker | H10: jac.mckinzie@bilearner.com | I10: NEL | J10: Active | K10: Contract | L10: Zone B | M10: Part-Time | N10: Unk | P10: Sales | Q10: Executive | R10: 27164 | S10: TX | T10: Executive Assistant | U10: Male | V10: 78789 | W10: Black | X10: Widowed | Y10: Exceeds | Z10: 3 | AA10: =IF(E10="","Active","Non-Active") -> Active | AB10: =YEAR(R10) -> 1974 | AC10: =INT(YEARFRAC(R10,"20/04/2026")) -> 51 | AD10: {=_xlfn.IFS(AB10<1965,"Baby Boomers",AB10<1981,"Gen X",AB10<1997,"Millenial",TRUE,("Gen Z"))} -> Gen X | AF10: 1 | AG10: =COUNTIF(Table1[Current Employee Rating],"1") -> 271
A11: 3436 | B11: Joseph | C11: Martins | D11: 44582 | E11: 45106 | F11: Area Sales Manager | G11: George Jenkins | H11: joseph.martins@bilearner.com | I11: BPC | J11: Active | K11: Part-Time | L11: Zone B | M11: Temporary | N11: Resignation | O11: Summer personal bag. | P11: Sales | Q11: Engineers | R11: 18213 | S11: TX | T11: Engineer | U11: Male | V11: 78207 | W11: Asian | X11: Widowed | Y11: Fully Meets | Z11: 5 | AA11: =IF(E11="","Active","Non-Active") -> Non-Active | AB11: =YEAR(R11) -> 1949 | AC11: =INT(YEARFRAC(R11,"20/04/2026")) -> 76 | AD11: {=_xlfn.IFS(AB11<1965,"Baby Boomers",AB11<1981,"Gen X",AB11<1997,"Millenial",TRUE,("Gen Z"))} -> Baby Boomers
A12: 3437 | B12: Myriam | C12: Givens | D12: 45142 | F12: Area Sales Manager | G12: Troy White | H12: myriam.givens@bilearner.com | I12: SVG | J12: Active | K12: Contract | L12: Zone B | M12: Temporary | N12: Unk | P12: Sales | Q12: Field Operations | R12: 23402 | S12: IN | T12: Technician | U12: Female | V12: 46204 | W12: Other | X12: Single | Y12: Fully Meets | Z12: 5 | AA12: =IF(E12="","Active","Non-Active") -> Active | AB12: =YEAR(R12) -> 1964 | AC12: =INT(YEARFRAC(R12,"20/04/2026")) -> 62 | AD12: {=_xlfn.IFS(AB12<1965,"Baby Boomers",AB12<1981,"Gen X",AB12<1997,"Millenial",TRUE,("Gen Z"))} -> Baby Boomers
A13: 3438 | B13: Dheepa | C13: Nguyen | D13: 43322 | E13: 43773 | F13: Area Sales Manager | G13: Brian Miller | H13: dheepa.nguyen@bilearner.com | I13: MSC | J13: Active | K13: Full-Time | L13: Zone C | M13: Temporary | N13: Retirement | O13: Alone once than. More condition pay far. | P13: Sales | Q13: General - Con | R13: 17629 | S13: GA | T13: Technician | U13: Female | V13: 30428 | W13: Asian | X13: Married | Y13: Fully Meets | Z13: 3 | AA13: =IF(E13="","Active","Non-Active") -> Non-Active | AB13: =YEAR(R13) -> 1948 | AC13: =INT(YEARFRAC(R13,"20/04/2026")) -> 78 | AD13: {=_xlfn.IFS(AB13<1965,"Baby Boomers",AB13<1981,"Gen X",AB13<1997,"Millenial",TRUE,("Gen Z"))} -> Baby Boomers
A14: 3439 | B14: Bartholemew | C14: Khemmich | D14: 44706 | E14: 44892 | F14: Area Sales Manager | G14: Charles Parks | H14: bartholemew.khemmich@bilearner.com | I14: EW | J14: Active | K14: Full-Time | L14: Zone A | M14: Temporary | N14: Involuntary | O14: Foot in theory minute recognize test. | P14: Sales | Q14: Splicing | R14: 29914 | S14: CO | T14: Splicer | U14: Male | V14: 80820 | W14: Other | X14: Single | Y14: Fully Meets | Z14: 3 | AA14: =IF(E14="","Active","Non-Active") -> Non-Active | AB14: =YEAR(R14) -> 1981 | AC14: =INT(YEARFRAC(R14,"20/04/2026")) -> 44 | AD14: {=_xlfn.IFS(AB14<1965,"Baby Boomers",AB14<1981,"Gen X",AB14<1997,"Millenial",TRUE,("Gen Z"))} -> Millenial
A15: 3440 | B15: Xana | C15: Potts | D15: 43804 | E15: 44974 | F15: Area Sales Manager | G15: Gregory Walker | H15: xana.potts@bilearner.com | I15: CCDR | J15: Active | K15: Contract | L15: Zone A | M15: Full-Time | N15: Resignation | O15: Degree wish science when thing week old. | P15: Sales | Q15: Finance & Accounting | R15: 18938 | S15: KY | T15: Controller | U15: Female | V15: 40220 | W15: White | X15: Divorced | Y15: Fully Meets | Z15: 3 | AA15: =IF(E15="","Active","Non-Active") -> Non-Active | AB15: =YEAR(R15) -> 1951 | AC15: =INT(YEARFRAC(R15,"20/04/2026")) -> 74 | AD15: {=_xlfn.IFS(AB15<1965,"Baby Boomers",AB15<1981,"Gen X",AB15<1997,"Millenial",TRUE,("Gen Z"))} -> Baby Boomers
A16: 3441 | B16: Prater | C16: Jeremy | D16: 43583 | F16: Area Sales Manager | G16: Tyler Lewis | H16: prater.jeremy@bilearner.com | I16: BPC | J16: Active | K16: Part-Time | L16: Zone A | M16: Part-Time | N16: Unk | P16: Sales | Q16: General - Con | R16: 32833 | S16: NV | T16: Lineman | U16: Male | V16: 89139 | W16: Asian | X16: Widowed | Y16: Exceeds | Z16: 4 | AA16: =IF(E16="","Active","Non-Active") -> Active | AB16: =YEAR(R16) -> 1989 | AC16: =INT(YEARFRAC(R16,"20/04/2026")) -> 36 | AD16: {=_xlfn.IFS(AB16<1965,"Baby Boomers",AB16<1981,"Gen X",AB16<1997,"Millenial",TRUE,("Gen Z"))} -> Millenial
A17: 3442 | B17: Kaylah | C17: Moon | D17: 43655 | E17: 44728 | F17: Area Sales Manager | G17: Ashley Scott | H17: kaylah.moon@bilearner.com | I17: PYZ | J17: Active | K17: Full-Time | L17: Zone A | M17: Full-Time | N17: Retirement | O17: Fear particular method stage. | P17: It/Is | Q17: Field Operations | R17: 19322 | S17: MA | T17: Laborer | U17: Male | V17: 2810 | W17: Black | X17: Single | Y17: Exceeds | Z17: 2 | AA17: =IF(E17="","Active","Non-Active") -> Non-Active | AB17: =YEAR(R17) -> 1952 | AC17: =INT(YEARFRAC(R17,"20/04/2026")) -> 73 | AD17: {=_xlfn.IFS(AB17<1965,"Baby Boomers",AB17<1981,"Gen X",AB17<1997,"Millenial",TRUE,("Gen Z"))} -> Baby Boomers
A18: 3443 | B18: Kristen | C18: Tate | D18: 44291 | E18: 45058 | F18: Area Sales Manager | G18: Lauren Jones | H18: kristen.tate@bilearner.com | I18: WBL | J18: Active | K18: Full-Time | L18: Zone C | M18: Part-Time | N18: Voluntary | O18: Wall body wonder successful. | P18: It/Is | Q18: Project Management - Con | R18: 34432 | S18: KY | T18: Coordinator | U18: Male | V18: 2621 | W18: Asian | X18: Widowed | Y18: Fully Meets | Z18: 3 | AA18: =IF(E18="","Active","Non-Active") -> Non-Active | AB18: =YEAR(R18) -> 1994 | AC18: =INT(YEARFRAC(R18,"20/04/2026")) -> 32 | AD18: {=_xlfn.IFS(AB18<1965,"Baby Boomers",AB18<1981,"Gen X",AB18<1997,"Millenial",TRUE,("Gen Z"))} -> Millenial
A19: 3444 | B19: Bobby | C19: Rodgers | D19: 44528 | E19: 44596 | F19: Area Sales Manager | G19: Matthew Jackson | H19: bobby.rodgers@bilearner.com | I19: NEL | J19: Active | K19: Contract | L19: Zone A | M19: Part-Time | N19: Voluntary | O19: Visit foot nearly radio treatment. | P19: Sales | Q19: Engineers | R19: 30635 | S19: KY | T19: Director | U19: Male | V19: 44553 | W19: Other | X19: Widowed | Y19: Fully Meets | Z19: 3 | AA19: =IF(E19="","Active","Non-Active") -> Non-Active | AB19: =YEAR(R19) -> 1983 | AC19: =INT(YEARFRAC(R19,"20/04/2026")) -> 42 | AD19: {=_xlfn.IFS(AB19<1965,"Baby Boomers",AB19<1981,"Gen X",AB19<1997,"Millenial",TRUE,("Gen Z"))} -> Millenial
A20: 3445 | B20: Reid | C20: Park | D20: 44212 | F20: Area Sales Manager | G20: Michelle Mitchell | H20: reid.park@bilearner.com | I20: PL | J20: Active | K20: Contract | L20: Zone C | M20: Full-Time | N20: Unk | P20: Sales | Q20: Project Management - Con | R20: 31388 | S20: KY | T20: Supervisor | U20: Female | V20: 5360 | W20: Other | X20: Married | Y20: Exceeds | Z20: 4 | AA20: =IF(E20="","Active","Non-Active") -> Active | AB20: =YEAR(R20) -> 1985 | AC20: =INT(YEARFRAC(R20,"20/04/2026")) -> 40 | AD20: {=_xlfn.IFS(AB20<1965,"Baby Boomers",AB20<1981,"Gen X",AB20<1997,"Millenial",TRUE,("Gen Z"))} -> Millenial
A21: 3446 | B21: Hector | C21: Dalton | D21: 44432 | F21: Area Sales Manager | G21: Sydney French | H21: hector.dalton@bilearner.com | I21: BPC | J21: Active | K21: Part-Time | L21: Zone A | M21: Part-Time | N21: Unk | P21: Sales | Q21: Field Operations | R21: 35186 | S21: TX | T21: Driller | U21: Female | V21: 16325 | W21: White | X21: Divorced | Y21: Exceeds | Z21: 2 | AA21: =IF(E21="","Active","Non-Active") -> Active | AB21: =YEAR(R21) -> 1996 | AC21: =INT(YEARFRAC(R21,"20/04/2026")) -> 29 | AD21: {=_xlfn.IFS(AB21<1965,"Baby Boomers",AB21<1981,"Gen X",AB21<1997,"Millenial",TRUE,("Gen Z"))} -> Millenial
A22: 3447 | B22: Mariela | C22: Schultz | D22: 43977 | E22: 45095 | F22: Area Sales Manager | G22: Michelle Evans Md | H22: mariela.schultz@bilearner.com | I22: CCDR | J22: Future Start | K22: Part-Time | L22: Zone C | M22: Part-Time | N22: Involuntary | O22: Unit pass office southern break one. | P22: Sales | Q22: General - Con | R22: 23424 | S22: TX | T22: Technician | U22: Female | V22: 43481 | W22: Asian | X22: Widowed | Y22: Fully Meets | Z22: 3 | AA22: =IF(E22="","Active","Non-Active") -> Non-Active | AB22: =YEAR(R22) -> 1964 | AC22: =INT(YEARFRAC(R22,"20/04/2026")) -> 62 | AD22: {=_xlfn.IFS(AB22<1965,"Baby Boomers",AB22<1981,"Gen X",AB22<1997,"Millenial",TRUE,("Gen Z"))} -> Baby Boomers
A23: 3448 | B23: Angela | C23: Molina | D23: 43739 | E23: 44141 | F23: Area Sales Manager | G23: Patricia Cook | H23: angela.molina@bilearner.com | I23: SVG | J23: Future Start | K23: Full-Time | L23: Zone A | M23: Temporary | N23: Retirement | O23: List class mind. | P23: Sales | Q23: Engineers | R23: 21317 | S23: TX | T23: Specialist | U23: Male | V23: 50705 | W23: Asian | X23: Widowed | Y23: Fully Meets | Z23: 3 | AA23: =IF(E23="","Active","Non-Active") -> Non-Active | AB23: =YEAR(R23) -> 1958 | AC23: =INT(YEARFRAC(R23,"20/04/2026")) -> 67 | AD23: {=_xlfn.IFS(AB23<1965,"Baby Boomers",AB23<1981,"Gen X",AB23<1997,"Millenial",TRUE,("Gen Z"))} -> Baby Boomers
A24: 3449 | B24: Gerald | C24: Preston | D24: 45056 | E24: 45073 | F24: Area Sales Manager | G24: Ashley Reeves | H24: gerald.preston@bilearner.com | I24: EW | J24: Future Start | K24: Contract | L24: Zone B | M24: Temporary | N24: Involuntary | O24: Price third parent evening. | P24: Sales | Q24: General - Eng | R24: 33865 | S24: CO | T24: Technician | U24: Male | V24: 5168 | W24: Black | X24: Single | Y24: Fully Meets | Z24: 5 | AA24: =IF(E24="","Active","Non-Active") -> Non-Active | AB24: =YEAR(R24) -> 1992 | AC24: =INT(YEARFRAC(R24,"20/04/2026")) -> 33 | AD24: {=_xlfn.IFS(AB24<1965,"Baby Boomers",AB24<1981,"Gen X",AB24<1997,"Millenial",TRUE,("Gen Z"))} -> Millenial
A25: 3450 | B25: Reilly | C25: Moyer | D25: 44075 | E25: 44899 | F25: Area Sales Manager | G25: Stanley Harvey | H25: reilly.moyer@bilearner.com | I25: MSC | J25: Active | K25: Contract | L25: Zone C | M25: Temporary | N25: Resignation | O25: Cause military a sense. Doctor property may. | P25: Sales | Q25: Field Operations | R25: 34557 | S25: CO | T25: Operator | U25: Male | V25: 11765 | W25: Other | X25: Single | Y25: Exceeds | Z25: 2 | AA25: =IF(E25="","Active","Non-Active") -> Non-Active | AB25: =YEAR(R25) -> 1994 | AC25: =INT(YEARFRAC(R25,"20/04/2026")) -> 31 | AD25: {=_xlfn.IFS(AB25<1965,"Baby Boomers",AB25<1981,"Gen X",AB25<1997,"Millenial",TRUE,("Gen Z"))} -> Millenial
A26: 3451 | B26: Carlee | C26: French | D26: 44245 | E26: 44876 | F26: Area Sales Manager | G26: Michael Bradshaw | H26: carlee.french@bilearner.com | I26: TNS | J26: Active | K26: Contract | L26: Zone C | M26: Full-Time | N26: Voluntary | O26: Station another son positive. | P26: Sales | Q26: General - Con | R26: 24852 | S26: CO | T26: Technician | U26: Male | V26: 71071 | W26: Other | X26: Divorced | Y26: Exceeds | Z26: 3 | AA26: =IF(E26="","Active","Non-Active") -> Non-Active | AB26: =YEAR(R26) -> 1968 | AC26: =INT(YEARFRAC(R26,"20/04/2026")) -> 58 | AD26: {=_xlfn.IFS(AB26<1965,"Baby Boomers",AB26<1981,"Gen X",AB26<1997,"Millenial",TRUE,("Gen Z"))} -> Gen X
A27: 3452 | B27: Jaydon | C27: Blackburn | D27: 44873 | F27: Area Sales Manager | G27: Debbie Crosby | H27: jaydon.blackburn@bilearner.com | I27: PYZ | J27: Active | K27: Part-Time | L27: Zone A | M27: Part-Time | N27: Unk | P27: Sales | Q27: General - Con | R27: 17174 | S27: IN | T27: Foreman | U27: Male | V27: 12122 | W27: Black | X27: Divorced | Y27: Fully Meets | Z27: 2 | AA27: =IF(E27="","Active","Non-Active") -> Active | AB27: =YEAR(R27) -> 1947 | AC27: =INT(YEARFRAC(R27,"20/04/2026")) -> 79 | AD27: {=_xlfn.IFS(AB27<1965,"Baby Boomers",AB27<1981,"Gen X",AB27<1997,"Millenial",TRUE,("Gen Z"))} -> Baby Boomers
A28: 3453 | B28: Bridger | C28: Carter | D28: 44847 | F28: Area Sales Manager | G28: Elizabeth Taylor | H28: bridger.carter@bilearner.com | I28: WBL | J28: Active | K28: Contract | L28: Zone C | M28: Part-Time | N28: Unk | P28: Sales | Q28: Fielders | R28: 30048 | S28: MA | T28: Engineer | U28: Male | V28: 87065 | W28: White | X28: Widowed | Y28: Fully Meets | Z28: 4 | AA28: =IF(E28="","Active","Non-Active") -> Active | AB28: =YEAR(R28) -> 1982 | AC28: =INT(YEARFRAC(R28,"20/04/2026")) -> 44 | AD28: {=_xlfn.IFS(AB28<1965,"Baby Boomers",AB28<1981,"Gen X",AB28<1997,"Millenial",TRUE,("Gen Z"))} -> Millenial
A29: 3454 | B29: Leon | C29: Beard | D29: 44815 | F29: Area Sales Manager | G29: Brian Dunlap | H29: leon.beard@bilearner.com | I29: PYZ | J29: Active | K29: Full-Time | L29: Zone C | M29: Full-Time | N29: Unk | P29: It/Is | Q29: General - Con | R29: 25597 | S29: KY | T29: Foreman | U29: Male | V29: 10415 | W29: Hispanic | X29: Married | Y29: Needs Improvement | Z29: 4 | AA29: =IF(E29="","Active","Non-Active") -> Active | AB29: =YEAR(R29) -> 1970 | AC29: =INT(YEARFRAC(R29,"20/04/2026")) -> 56 | AD29: {=_xlfn.IFS(AB29<1965,"Baby Boomers",AB29<1981,"Gen X",AB29<1997,"Millenial",TRUE,("Gen Z"))} -> Gen X
A30: 3455 | B30: Charity | C30: Miranda | D30: 44376 | E30: 44747 | F30: Area Sales Manager | G30: Daniel Rodriguez | H30: charity.miranda@bilearner.com | I30: WBL | J30: Active | K30: Full-Time | L30: Zone C | M30: Temporary | N30: Resignation | O30: Pm local take example fund. Small heavy listen. | P30: Sales | Q30: Project Management - Eng | R30: 36178 | S30: KY | T30: Manager | U30: Male | V30: 3763 | W30: Other | X30: Widowed | Y30: Exceeds | Z30: 4 | AA30: =IF(E30="","Active","Non-Active") -> Non-Active | AB30: =YEAR(R30) -> 1999 | AC30: =INT(YEARFRAC(R30,"20/04/2026")) -> 27 | AD30: {=_xlfn.IFS(AB30<1965,"Baby Boomers",AB30<1981,"Gen X",AB30<1997,"Millenial",TRUE,("Gen Z"))} -> Gen Z
A31: 3456 | B31: Axel | C31: Howe | D31: 44991 | F31: Area Sales Manager | G31: Martin Hammond | H31: axel.howe@bilearner.com | I31: NEL | J31: Active | K31: Full-Time | L31: Zone A | M31: Temporary | N31: Unk | P31: Sales | Q31: Field Operations | R31: 17070 | S31: KY | T31: Technician | U31: Female | V31: 79623 | W31: Black | X31: Divorced | Y31: Fully Meets | Z31: 3 | AA31: =IF(E31="","Active","Non-Active") -> Active | AB31: =YEAR(R31) -> 1946 | AC31: =INT(YEARFRAC(R31,"20/04/2026")) -> 79 | AD31: {=_xlfn.IFS(AB31<1965,"Baby Boomers",AB31<1981,"Gen X",AB31<1997,"Millenial",TRUE,("Gen Z"))} -> Baby Boomers
A32: 3457 | B32: Milton | C32: Wall | D32: 44099 | F32: Area Sales Manager | G32: Sara Bell | H32: milton.wall@bilearner.com | I32: PL | J32: Active | K32: Full-Time | L32: Zone B | M32: Temporary | N32: Unk | P32: Sales | Q32: Engineers | R32: 17402 | S32: KY | T32: Technician | U32: Female | V32: 69189 | W32: White | X32: Divorced | Y32: Needs Improvement | Z32: 3 | AA32: =IF(E32="","Active","Non-Active") -> Active | AB32: =YEAR(R32) -> 1947 | AC32: =INT(YEARFRAC(R32,"20/04/2026")) -> 78 | AD32: {=_xlfn.IFS(AB32<1965,"Baby Boomers",AB32<1981,"Gen X",AB32<1997,"Millenial",TRUE,("Gen Z"))} -> Baby Boomers
A33: 3458 | B33: Cory | C33: Robinson | D33: 44679 | E33: 45070 | F33: Area Sales Manager | G33: Elizabeth Anderson | H33: cory.robinson@bilearner.com | I33: BPC | J33: Future Start | K33: Contract | L33: Zone A | M33: Full-Time | N33: Voluntary | O33: Several young whether that expert. | P33: Sales | Q33: Field Operations | R33: 35289 | S33: TX | T33: Laborer | U33: Female | V33: 5194 | W33: Hispanic | X33: Single | Y33: Needs Improvement | Z33: 3 | AA33: =IF(E33="","Active","Non-Active") -> Non-Active | AB33: =YEAR(R33) -> 1996 | AC33: =INT(YEARFRAC(R33,"20/04/2026")) -> 29 | AD33: {=_xlfn.IFS(AB33<1965,"Baby Boomers",AB33<1981,"Gen X",AB33<1997,"Millenial",TRUE,("Gen Z"))} -> Millenial
A34: 3459 | B34: Saniya | C34: Yu | D34: 44304 | E34: 44733 | F34: Area Sales Manager | G34: Erin Bailey | H34: saniya.yu@bilearner.com | I34: CCDR | J34: Future Start | K34: Part-Time | L34: Zone A | M34: Full-Time | N34: Retirement | O34: Science end approach democratic treatment. | P34: Sales | Q34: General - Con | R34: 16111 | S34: TX | T34: Splicer | U34: Male | V34: 8779 | W34: Black | X34: Widowed | Y34: Exceeds | Z34: 2 | AA34: =IF(E34="","Active","Non-Active") -> Non-Active | AB34: =YEAR(R34) -> 1944 | AC34: =INT(YEARFRAC(R34,"20/04/2026")) -> 82 | AD34: {=_xlfn.IFS(AB34<1965,"Baby Boomers",AB34<1981,"Gen X",AB34<1997,"Millenial",TRUE,("Gen Z"))} -> Baby Boomers
A35: 3460 | B35: Alisa | C35: James | D35: 43880 | F35: Area Sales Manager | G35: Dennis Henderson | H35: alisa.james@bilearner.com | I35: SVG | J35: Active | K35: Full-Time | L35: Zone A | M35: Full-Time | N35: Unk | P35: Sales | Q35: Aerial | R35: 16112 | S35: TX | T35: Lineman | U35: Male | V35: 74682 | W35: Asian | X35: Married | Y35: Fully Meets | Z35: 3 | AA35: =IF(E35="","Active","Non-Active") -> Active | AB35: =YEAR(R35) -> 1944 | AC35: =INT(YEARFRAC(R35,"20/04/2026")) -> 82 | AD35: {=_xlfn.IFS(AB35<1965,"Baby Boomers",AB35<1981,"Gen X",AB35<1997,"Millenial",TRUE,("Gen Z"))} -> Baby Boomers
A36: 3461 | B36: Lincoln | C36: Compton | D36: 43664 | E36: 44470 | F36: Area Sales Manager | G36: Tammy Conner | H36: lincoln.compton@bilearner.com | I36: EW | J36: Future Start | K36: Full-Time | L36: Zone C | M36: Part-Time | N36: Resignation | O36: Base scene central unit per argue. Might last of. | P36: Sales | Q36: General - Con | R36: 35793 | S36: CO | T36: Foreman | U36: Male | V36: 78046 | W36: Hispanic | X36: Married | Y36: Needs Improvement | Z36: 1 | AA36: =IF(E36="","Active","Non-Active") -> Non-Active | AB36: =YEAR(R36) -> 1997 | AC36: =INT(YEARFRAC(R36,"20/04/2026")) -> 28 | AD36: {=_xlfn.IFS(AB36<1965,"Baby Boomers",AB36<1981,"Gen X",AB36<1997,"Millenial",TRUE,("Gen Z"))} -> Gen Z
A37: 3462 | B37: Aliana | C37: Nolan | D37: 43356 | E37: 44456 | F37: Area Sales Manager | G37: Brianna Mathews | H37: aliana.nolan@bilearner.com | I37: MSC | J37: Active | K37: Contract | L37: Zone A | M37: Full-Time | N37: Involuntary | O37: Yourself book budget product. | P37: Sales | Q37: Field Operations | R37: 15562 | S37: CO | T37: Coordinator | U37: Male | V37: 27270 | W37: Hispanic | X37: Divorced | Y37: Needs Improvement | Z37: 3 | AA37: =IF(E37="","Active","Non-Active") -> Non-Active | AB37: =YEAR(R37) -> 1942 | AC37: =INT(YEARFRAC(R37,"20/04/2026")) -> 83 | AD37: {=_xlfn.IFS(AB37<1965,"Baby Boomers",AB37<1981,"Gen X",AB37<1997,"Millenial",TRUE,("Gen Z"))} -> Baby Boomers
A38: 3463 | B38: Kayden | C38: Dodson | D38: 43951 | E38: 44395 | F38: Area Sales Manager | G38: Jessica Peters | H38: kayden.dodson@bilearner.com | I38: TNS | J38: Active | K38: Part-Time | L38: Zone A | M38: Temporary | N38: Retirement | O38: Paper can score else investment. | P38: Sales | Q38: Field Operations | R38: 18800 | S38: IN | T38: Tower Hand | U38: Male | V38: 12703 | W38: Hispanic | X38: Single | Y38: Fully Meets | Z38: 1 | AA38: =IF(E38="","Active","Non-Active") -> Non-Active | AB38: =YEAR(R38) -> 1951 | AC38: =INT(YEARFRAC(R38,"20/04/2026")) -> 74 | AD38: {=_xlfn.IFS(AB38<1965,"Baby Boomers",AB38<1981,"Gen X",AB38<1997,"Millenial",TRUE,("Gen Z"))} -> Baby Boomers
A39: 3464 | B39: James | C39: Duke | D39: 43437 | E39: 44813 | F39: Area Sales Manager | G39: Mark Harris | H39: james.duke@bilearner.com | I39: PYZ | J39: Active | K39: Contract | L39: Zone B | M39: Full-Time | N39: Involuntary | O39: Stuff different color how. | P39: Sales | Q39: Shop (Fleet) | R39: 35963 | S39: MA | T39: Mechanic | U39: Male | V39: 66835 | W39: Black | X39: Widowed | Y39: Needs Improvement | Z39: 5 | AA39: =IF(E39="","Active","Non-Active") -> Non-Active | AB39: =YEAR(R39) -> 1998 | AC39: =INT(YEARFRAC(R39,"20/04/2026")) -> 27 | AD39: {=_xlfn.IFS(AB39<1965,"Baby Boomers",AB39<1981,"Gen X",AB39<1997,"Millenial",TRUE,("Gen Z"))} -> Gen Z
A40: 3465 | B40: Willow | C40: Stuart | D40: 44508 | F40: Area Sales Manager | G40: Elizabeth Tapia | H40: willow.stuart@bilearner.com | I40: WBL | J40: Active | K40: Full-Time | L40: Zone B | M40: Full-Time | N40: Unk | P40: Sales | Q40: General - Con | R40: 22653 | S40: MA | T40: Flagger | U40: Male | V40: 66150 | W40: Asian | X40: Divorced | Y40: Needs Improvement | Z40: 3 | AA40: =IF(E40="","Active","Non-Active") -> Active | AB40: =YEAR(R40) -> 1962 | AC40: =INT(YEARFRAC(R40,"20/04/2026")) -> 64 | AD40: {=_xlfn.IFS(AB40<1965,"Baby Boomers",AB40<1981,"Gen X",AB40<1997,"Millenial",TRUE,("Gen Z"))} -> Baby Boomers
...

Sheet DATA FORMULASI
